Workbook

Sheet 9-1.소요예산 산출내역
B1: 9-1. 소요예산 산출내역 | R1: 2026.06.11. | T1: 소요예산 총괄표 <자동입력>
B2: 과제명: 근무규칙 전부 반영 병동 간호인력 배수표 개발: 합성 근무표 편성가능성 계산실험에 의한 산술 하한과 조합 프리미엄의 산정 | T2: 연구비목 | V2: 금액(원) | W2: 구성비(%)
B3: 연구기간: 12개월 (연구 개시일은 협약 시 확정) | T3: 1. 직접비 | U3: ①인건비 | V3: =O10 | W3: =IFERROR(V3/V9,"-")
U4: ②연구시설장비비 | V4: =O17 | W4: =IFERROR(V4/$V$9,"-")
B5: * 작성방법: 붉은색 글씨 표시된 부분 작성 | L5: 달러당 환율: | O5: 1500 | P5: 원 | U5: ③연구재료비 | V5: =O26 | W5: =IFERROR(V5/$V$9,"-")
B6: Ⅰ. 직접비 | O6: 금액 | Q6: 비고 | U6: ④연구활동비 | V6: =O31 | W6: =IFERROR(V6/$V$9,"-")
B7: ○ 직접비 합계 | O7: =O10+O17+O26+O31+O76 | U7: ⑤위탁연구개발비 | V7: =O76 | W7: =IFERROR(V7/$V$9,"-")
T8: 2. 간접비(직접비의 6%) | V8: =O84 | W8: =IFERROR(V8/$V$9,"-")
B9: 1. 인건비 ('26 기재부 학술연구용역 인건비 기준단가 적용) | O9: 금액 | P9: 구성비 | T9: 합계 | V9: =SUM(V3:V8) | W9: =IFERROR(V9/$V$9,"-")
B10: ○ 인건비 합계 | O10: =SUM(O12:O14) | P10: =IFERROR(O10/$O$7,"-") | Q10: 직접비 대비 인건비 비율
C11: 등급 | D11: <자동입력> | F11: 인건비계상율 | I11: 인원 | L11: 개월
C12: 연구원 | D12: =마스터!C4 | E12: × | F12: 0.1 | G12: % | H12: × | I12: 0 | J12: 명 | K12: × | L12: 0 | M12: 월 | N12: = | O12: =D12*F12*I12*L12
C13: 연구보조원 | D13: =마스터!C5 | E13: × | F13: 0.05 | G13: % | H13: × | I13: 0 | J13: 명 | K13: × | L13: 0 | M13: 월 | N13: = | O13: =D13*F13*I13*L13
C14: 보조원 | D14: =마스터!C6 | E14: × | F14: 0.05 | G14: % | H14: × | I14: 0 | J14: 명 | K14: × | L14: 0 | M14: 월 | N14: = | O14: =D14*F14*I14*L14
B16: 2. 연구 시설·장비비 (단, 범용성 장비에 대해서는 총 연구비 10% 이내) | O16: 금액 | P16: 구성비
B17: ○ 연구시설장비비 합계 | O17: =O18+O22 | P17: =IFERROR(O17/$O$7,"-") | Q17: 직접비 대비 연구시설장비비 비율
B18: ▶ 연구시설, 장비 구매 | D18: 단가(부가세 포함) | O18: =SUM(O19:O21) | P18: =IFERROR(O18/$O$7,"-")
C19: 신규 장비명 | D19: 0 | E19: × | G19: 개 | N19: = | O19: =D19*F19
C20: s/w명 | D20: 0 | E20: × | G20: 개 | N20: = | O20: =D20*F20
C21: 비품명 | D21: 0 | E21: × | G21: 개 | N21: = | O21: =D21*F21
B22: ▶ 범용성 장비 구매(총 연구비의 10% 이내) | O22: =SUM(O23) | P22: =IFERROR(O22/O87,"-") | Q22: 붉은색표시-기준초과 수정필요
C23: 범용성 장비명 | E23: × | G23: 개 | N23: = | O23: =D23*F23 | P23: =IFERROR(O23/$O$7,"-")
B25: 3. 연구재료비 | O25: 금액 | P25: 구성비
B26: ○ 연구재료비 합계 | D26: 단가(부가세 포함) | O26: =SUM(O27:O28) | P26: =IFERROR(O26/$O$7,"-") | Q26: 직접비 대비 연구재료비 비율
C27: 시약재료 구입비 | D27: 0 | E27: × | F27: 0 | G27: 개 | H27: × | I27: 0 | J27: 회 | N27: = | O27: =D27*F27*I27 | Q27: 견적서 별첨 또는 계획서 견적서 서식 작성
D28: 0 | E28: × | F28: 0 | G28: 개 | H28: × | I28: 0 | J28: 회 | N28: = | O28: =D28*F28*I28
B30: 4. 연구활동비 | O30: 금액 | P30: 구성비 | Q30: 비고 | R30: 등급
B31: ○ 연구활동비 합계 | O31: =O38+O32+O49+O63+O57+O69+O54+O46 | P31: =IFERROR(O31/$O$7,"-") | Q31: 직접비 대비 연구활동비 비율
B32: ▶ 국내여비 | D32: 추정금액 | O32: =SUM(O33:O37) | P32: =IFERROR(O32/$O$7,"-") | Q32: 마스터-국내 여비 등급 구분표 참고
C33: 운임비 실비(공통) — 학회 발표 2회 × 1인당 편도 4회 | D33: 50000 | E33: × | F33: 2 | G33: 명 | H33: × | I33: 4 | J33: 회 | N33: = | O33: =D33*F33*I33 | Q33: 실비 기재
C34: 숙박비 실비(원장&관리직) | D34: 0 | E34: × | F34: 0 | G34: 명 | H34: × | I34: 0 | J34: 박 | N34: = | O34: =D34*F34*I34 | Q34: 실비 기재 | R34: 마스터 "국내 숙박비 등급" 입력
C35: 숙박비 상한액(그외 직원) | D35: =VLOOKUP(R35,마스터!$C$10:$E$15,3,FALSE) | E35: × | F35: 2 | G35: 명 | H35: × | I35: 2 | J35: 박 | N35: = | O35: =D35*F35*I35 | R35: 가
C36: 일비 정액(공통) | D36: 25000 | E36: × | F36: 2 | G36: 명 | H36: × | I36: 4 | J36: 일 | N36: = | O36: =D36*F36*I36
C37: 식비 정액(공통) | D37: 25000 | E37: × | F37: 2 | G37: 명 | H37: × | I37: 4 | J37: 일 | N37: = | O37: =D37*F37*I37 | R37: 나
B38: ▶ 국외여비 | O38: =SUM(O42:O45) | P38: =IFERROR(O38/$O$7,"-") | Q38: 붉은색표시-기준초과 수정필요
C39: 항공운임비 실비(공통) | D39: 0 | E39: × | F39: 0 | G39: 명 | H39: × | I39: 0 | J39: 회 | N39: = | O39: =D39*F39*I39 | Q39: 실비 기재 | R39: 마스터 "국외여비등급" 입력
C40: 숙박비 상한액(원장, 관리직) | D40: =VLOOKUP($R$40,마스터!$C$19:$F$34,3,FALSE) | E40: × | F40: 0 | G40: 명 | H40: × | I40: 0 | J40: 박 | K40: × | L40: =O5 | M40: 환율 | N40: = | O40: =D40*F40*I40*L40 | R40: 1
C41: 숙박비 상한액(그외 직원) | D41: =VLOOKUP($R$41,마스터!$C$19:$F$34,2,FALSE) | E41: × | F41: 0 | G41: 명 | H41: × | I41: 0 | J41: 박 | K41: × | L41: =O5 | M41: 환율 | N41: = | O41: =D41*F41*I41*L41 | R41: 8
C42: 일비 정액(원장, 관리직) | D42: =VLOOKUP($R$40,마스터!$C$19:$F$34,2,FALSE) | E42: × | F42: 0 | G42: 명 | H42: × | I42: 0 | J42: 일 | K42: × | L42: =O5 | M42: 환율 | N42: = | O42: =D42*F42*I42*L42 | Q42: 마스터-국외 여비 등급 구분표 참고
C43: 일비 정액(그외 직원) | D43: =VLOOKUP($R$41,마스터!$C$19:$F$34,2,FALSE) | E43: × | F43: 0 | G43: 명 | H43: × | I43: 0 | J43: 일 | K43: × | L43: =O5 | M43: 환율 | N43: = | O43: =D43*F43*I43*L43
...

Sheet 마스터
A1: 학술연구용역인건비기준단가(2026년)
A2: 등 급 | B2: 월 임금(’26) 50% | C2: 월 임금(’26) 100% | D2: 연봉(참여율 100%)
A3: 책임연구원 | B3: 3783728 | C3: =B3*2 | D3: =C3*12
A4: 연구원 | B4: 2901312 | C4: =B4*2 | D4: =C4*12
A5: 연구보조원 | B5: 1939429 | C5: =B5*2 | D5: =C5*12
A6: 보조원 | B6: 1454621 | C6: =B6*2 | D6: =C6*12
A8: 국내 숙박비 등급 구분표
A9: 도시종류 | B9: 구분 | C9: 등급(입력값) | D9: 식비 | E9: 숙박비상한액 | F9: 일비
A10: 수도권 | B10: 원장, 관리직 | C10: - | D10: 25000 | E10: 전액(실비입력필요) | F10: 25000
B11: 그외 전직원 | C11: 가 | D11: 25000 | E11: 100000
A12: 광역시 | B12: 원장, 관리직 | C12: - | D12: 25000 | E12: 전액(실비입력필요)
B13: 그외 전직원 | C13: 나 | D13: 25000 | E13: 80000
A14: 그외도시 | B14: 원장, 관리직 | C14: - | D14: 25000 | E14: 전액(실비입력필요)
B15: 그외 전직원 | C15: 다 | D15: 25000 | E15: 70000
A17: 국외 여비 등급 구분표
A18: 도시 | B18: 구분 | C18: 등급(입력값) | D18: 일비 | E18: 숙박비상한액(실비) | F18: 식비
A19: 도쿄, 뉴욕, 런던, 로스엔젤레스, 모스크바, 샌프란시스코, 워싱턴 D.C., 파리, 홍콩, 제네바, 싱가포르 | B19: 원장 | C19: 1 | D19: 50 | E19: 389 | F19: 160
B20: 관리직 | C20: 2 | D20: 40 | E20: 282 | F20: 133
B21: 의사직, 연구직(수석연구원, 책임연구원), 의학물리학직(1-2급), 일반직(1-2급) | C21: 3 | D21: 35 | E21: 223 | F21: 107
B22: 위를 제외한 전 직원 | C22: 4 | D22: 30 | E22: 176 | F22: 81
A23: 베이징, 사모아, 오스트레일리아, 인도, 일본, 카자흐스탄, 쿡제도, 타이완, 파푸아뉴기니,멕시코, 미국, 바베이도스, 세인트루시아, 세인트빈센트그레나딘, 세인트키츠네비스, 아이티, 앤티가바부다, 자메이카, 캐나다, 트리니다드토바고, 그리스, 네덜란드, 노르웨이, 덴마크, 독일, 러시아, 룩셈부르크, 벨기에, 사이프러스, 스웨덴, 스위스, 스페인, 아이슬란드, 아일랜드, 영국, 오스트리아, 이탈리아, 포르투칼, 프랑스, 핀란드, 헝가리, 가나, 가봉, 남수단, 남아프리카공화국, 리비아, 모로코, 바레인, 사우디아라비아, 세이셸, 아랍에미리트, 앙골라, 에티오피아, 오만, 우간다, 이스라엘, 이집트, 적도기니, 카타르, 코트디부아르, 콩고민주공화국, 쿠웨이트 | B23: 원장 | C23: 5 | D23: 50 | E23: 289 | F23: 117
B24: 관리직 | C24: 6 | D24: 40 | E24: 207 | F24: 99
B25: 의사직, 연구직(수석연구원, 책임연구원), 의학물리학직(1-2급), 일반직(1-2급) | C25: 7 | D25: 35 | E25: 160 | F25: 78
B26: 위를 제외한 전 직원 | C26: 8 | D26: 30 | E26: 137 | F26: 59
A27: 뉴질랜드, 니우에, 마셜군도, 말레이시아, 방글라데시, 브루나이, 아제르바이잔, 인도네시아, 중국, 키르키즈공화국, 타이, 터키, 투르크메니스탄, 파키스탄, 피지, 가이아나, 과테말라, 도미니카공화국, 베네수엘라, 벨리즈, 브라질, 아르헨티나, 에콰도르, 우루과이, 칠레, 코스타리카, 파나마, 라트비아, 루마니아, 리투아니아, 몬테네그로, 불가리아, 세르비아, 슬로바키아, 슬로베니아, 에스토니아, 우크라이나, 체코, 크로아티아, 폴란드, 기니, 나이지리아, 니제르, 라이베리아, 레바논, 르완다, 말리, 모리셔스, 모잠비크, 보츠와나, 부르키나파소, 상투메프린시페, 세네갈, 수단, 스와질란드, 시에라리온, 아프가니스탄, 알제리, 요르단, 이라크, 잠비아, 중앙아프리카공화국, 카메룬, 케냐, 탄자니아 | B27: 원장 | C27: 9 | D27: 50 | E27: 215 | F27: 87
B28: 관리직 | C28: 10 | D28: 40 | E28: 162 | F28: 72
B29: 의사직, 연구직(수석연구원, 책임연구원), 의학물리학직(1-2급), 일반직(1-2급) | C29: 11 | D29: 35 | E29: 130 | F29: 58
B30: 위를 제외한 전 직원 | C30: 12 | D30: 30 | E30: 106 | F30: 44
A31: 네팔, 동티모르, 라오스, 몽골, 미얀마, 미크로네시아, 베트남, 스리랑카, 우즈베키스탄, 캄보디아, 타지키스탄, 통가, 필리핀, 니카라과, 볼리비아, 수리남, 엘살바도르, 온두라스, 콜롬비아, 파라과이, 페루,마케도니아, 몰도바, 벨라루스, 보스니아헤르체코비나, 알바니아, 감비아, 기니비사우, 나미비아, 레소토, 마다가스카르, 말라위, 모리타니, 소말리아, 예멘, 이란, 짐바브웨, 튀니지 | B31: 원장 | C31: 13 | D31: 50 | E31: 161 | F31: 73
B32: 관리직 | C32: 14 | D32: 40 | E32: 108 | F32: 61
B33: 의사직, 연구직(수석연구원, 책임연구원), 의학물리학직(1-2급), 일반직(1-2급) | C33: 15 | D33: 35 | E33: 85 | F33: 49
B34: 위를 제외한 전 직원 | C34: 16 | D34: 30 | E34: 81 | F34: 37
